Workbook

Sheet Bìa
A1: Tên system | K1: Loại system | W1: TKCB | AP1: Người tạo | AT1: Ngày tạo | AY1: Người update | BC1: Ngày update | BH1: Version
A2: Manage User | K2: Thiết kế màn hình | AP2: LongLD | AT2: 45078 | AY2: LongLD | BC2: 45078 | BH2: 0.1
A4: Category chức năng | U4: Hạng mục | AP4: Bìa
L16: Manage User
L24: =K2&"/"&H4&"/"&Z4 -> Thiết kế màn hình//
Q44: Ngày phê chuẩn | AA44: Người phê chuẩn | AQ44: Version

Sheet Lịch sử thay đổi
A1: Tên system | K1: Loại system | W1: =IF(Bìa!W1="","",Bìa!W1) -> TKCB | AP1: Người tạo | AT1: Ngày tạo | AY1: Người update | BC1: Ngày update | BH1: Version
A2: =IF(Bìa!A2="","",Bìa!A2) -> Manage User | K2: =IF(Bìa!K2="","",Bìa!K2) -> Thiết kế màn hình | AP2: =IF(Bìa!AP2="","",Bìa!AP2) -> LongLD | AT2: =IF(Bìa!AT2="","",Bìa!AT2) -> 45078 | AY2: =IF(Bìa!AY2="","",Bìa!AY2) -> LongLD | BC2: =IF(Bìa!BC2="","",Bìa!BC2) -> 45078 | BH2: 0.1
A4: Category chức năng | H4: =IF(Bìa!H4="","",Bìa!H4) | U4: Hạng mục | Z4: =IF(Bìa!Z4="","",Bìa!Z4) | AP4: Lịch sử thay đổi
B7: ■Lịch sử thay đổi
B9: Date | H9: Người thay đổi | O9: Version | S9: Nội dung thay đổi | AX9: Ngày phê chuẩn | BD9: Người phê chuẩn
B10: 45078 | H10: LongLD | O10: 0.1 | S10: Tạo mới

Sheet Layout MH
A1: Tên system | K1: Loại system | W1: =IF(Bìa!W1="","",Bìa!W1) -> TKCB | AZ1: Người tạo | BD1: Ngày tạo | BI1: Người update | BM1: Ngày update | BR1: Version
A2: =IF(Bìa!A2="","",Bìa!A2) -> Manage User | K2: =IF(Bìa!K2="","",Bìa!K2) -> Thiết kế màn hình | AZ2: =IF(Bìa!AP2="","",Bìa!AP2) -> LongLD | BD2: =IF(Bìa!AT2="","",Bìa!AT2) -> 45078 | BI2: =IF(Bìa!AY2="","",Bìa!AY2) -> LongLD | BM2: =IF(Bìa!BC2="","",Bìa!BC2) -> 45078 | BR2: =IF(Bìa!BH2="","",Bìa!BH2) -> 0.1
A4: Category chức năng | H4: =IF(Bìa!H4="","",Bìa!H4) | U4: Hạng mục | Z4: =IF(Bìa!Z4="","",Bìa!Z4) | AZ4: Layout MH
B7: ■Login (ADM001)
BA8: Màn hình yêu cầu nhập username/password để vào hệ thống
BA10: URL vào là http(s)://ip_address/login
B42: ■ Nhân viên > List nhân viên (ADM002)
AZ43: Màn hình list nhân viên
BA45: URL vào là http(s)://ip_address/user/list
BA47: Có các chức năng chính
BB48: Search: search all và điều kiện (có sort)
BB49: Add: Link đến màn hình add mới ADM004
BB50: Sort: sort theo các trường
BC51: 氏名 (name)
BC52: 日本語能力 (trình độ JP)
BC53: 失効日 (ngày chứng chỉ JP hết hạn)
BB54: Chi tiết: Link đến màn hình chi tiết ADM003
BB55: Paging: Phân trang, mỗi page 20 bản ghi
B74: ■ Nhân viên > Chi tiết nhân viên (ADM003)
BA75: Màn hình hiển thị chi tiết nhân viên
BA79: Có các chức năng chính:
BA80: View: chi tiết một nhận viên
BA81: Edit: Link đến màn hình edit nhân viên ADM004
BA82: Delete: Delete nhân viên trong CSDL
B108: ■ Nhân viên > Edit\Add nhân viên (ADM004)
BA109: Màn hình edit/add nhân viên
BA113: Khi đi từ màn hình chi tiết: Sẽ là màn hình edit nhân viên
BA114: Khi đi từ màn hình list nhân viên: Sẽ là màn hình add nhân viên
BA116: Có các chức năng chính
BB117: Edit/Add: Link đến màn hình confirm ADM005
BA119: Hiển thị ban đầu:
BB120: `- Trường hợp add: các Trường để rỗng
BB121: `- Trường hợp edit: các Trường hiển thị thông tin của nhân viên
B141: ■ Nhân viên > Confirm add\edit nhân viên (ADM005)
BA142: Màn hình xác nhận thông tin nhân viên trước khi update vào database
BA145: Hiển thị ban đầu:
BB146: Hiện thi thông tin hợp lệ do user nhập vào từ màn hình add\edit
BB147: để xác nhận trước khi update vào database
BA149: Có các chức năng chính
BB151: Edit/Add: Gọi API để update vào database
...

Sheet Định nghĩa hạng mục
A1: Tên system | K1: Loại system | W1: =IF(Bìa!W1="","",Bìa!W1) -> TKCB | AT1: Người tạo | AX1: Ngày tạo | BC1: Người update | BG1: Ngày update | BL1: Version
A2: =IF(Bìa!A2="","",Bìa!A2) -> Manage User | K2: =IF(Bìa!K2="","",Bìa!K2) -> Thiết kế màn hình | AT2: =IF(Bìa!AP2="","",Bìa!AP2) -> LongLD | AX2: =IF(Bìa!AT2="","",Bìa!AT2) -> 45078 | BC2: =IF(Bìa!AY2="","",Bìa!AY2) -> LongLD | BG2: =IF(Bìa!BC2="","",Bìa!BC2) -> 45078 | BL2: =IF(Bìa!BH2="","",Bìa!BH2) -> 0.1
A4: Category chức năng | H4: =IF(Bìa!H4="","",Bìa!H4) | U4: Hạng mục | Z4: =IF(Bìa!Z4="","",Bìa!Z4) | AT4: Định nghĩa hạng mục
B7: ■Login (ADM001)
B8: No | D8: Tên hạng mục | M8: I/O | O8: Bắt buộc | Q8: Loại control | V8: Type | Z8: Min ký tự | AB8: Max ký tự | AD8: Format | AH8: Mapping hạng mục | AX8: Note
AH9: API tham chiếu | AN9: Trường tham chiếu
B10: 1 | D10: Logo | M10: O | O10: － | Q10: Image | V10: － | AX10: Logo công ty
B11: 2 | D11: Title | M11: O | O11: － | Q11: Label | V11: － | AX11: Text cố định
B12: 3 | D12: Username | M12: I | O12: 〇 | Q12: Text | V12: Tiếng Anh halfsize | AB12: 50
B13: 4 | D13: Password | M13: I | O13: 〇 | Q13: Password | V13: Tiếng Anh halfsize | Z13: 8 | AB13: 25
B14: 5 | D14: Login | M14: O | O14: － | Q14: Button | V14: － | AX14: Thực hiện gọi API login
B17: ■ Nhân viên > List nhân viên (ADM002)
B18: No | D18: Tên hạng mục | M18: I/O | O18: Bắt buộc | Q18: Loại control | V18: Type | Z18: Min ký tự | AB18: Max ký tự | AD18: Format | AH18: Mapping hạng mục | AX18: Note
AH19: API tham chiếu | AN19: Trường tham chiếu
B20: 1 | D20: Logo | M20: O | O20: － | Q20: Image | V20: － | AX20: Logo công ty + text tên cty: Luvina Software
B21: 2 | D21: Sign out | M21: O | O21: － | Q21: Link | V21: － | AX21: Clear storage, chuyển sang màn hình login ADM001
B22: 3 | D22: Top | M22: O | O22: － | Q22: Link | V22: － | AX22: Khi user click vào link scroll MH lên top
B23: 4 | D23: Title | M23: O | O23: － | Q23: Label | V23: － | AX23: Text cố định
B24: 5 | D24: Title hạng mục search Fullname | M24: O | O24: － | Q24: Label | V24: － | AX24: Text cố định
B25: 6 | D25: Điều kiện search Fullname | M25: I | O25: － | Q25: Text | V25: － | Z25: 0 | AB25: 125 | AX25: Nếu fullname là rỗng thì ko search fullname, ngược lại điều kiện search là mapping một phần( LIKE %Fullname%) Trên MH nhập fix cố định cho phép user chỉ nhập tối đa 125 kí tự
B26: 7 | D26: Title hạng mục search Department | M26: O | O26: － | Q26: Label | V26: － | AX26: Text cố định
B27: 8 | D27: Điều kiện search Department | M27: I | O27: － | Q27: Dropdown List | V27: － | AH27: API List departments | AN27: giá trị là department id label là department name | AX27: Dropdown giá trị là danh sách phòng ban Cho phép chọn rỗng (phần tử đầu là rỗng). Nêú user chọn rỗng thì ko search department, ngược lại search theo department id
B28: 9 | D28: Button Search | M28: － | O28: － | Q28: Button | V28: － | AX28: Thực hiện search (gọi API List employees) theo điều kiện search
B29: 10 | D29: Button Add mới | M29: － | O29: － | Q29: Button | V29: － | AX29: chuyển sang màn hình add mới ADM004
B30: 11 | D30: Header Bảng danh sách nhân viên | M30: O | Q30: Label | V30: － | AX30: Có các cột: ID, 氏名, 生年月日, グループ,メールアドレス,電話番号,日本語能力, 失効日, 点数. Trong đó: các cột 氏名, 日本語能力, 失効日 có biểu tượng sort, khi click vào toàn bộ title của cột thì thực hiện sort tại server (gọi API),mặc định ban đầu tất cả đều sort theo asc (biểu tượng ▲▽), khi click vào cột nào thì sort đảo ngược trạng thái sort hiện tại. Ví dụ: trạng thái cột đang là asc (▲▽), click vào title thì chuyển thành desc (▼△) và gọi API để sort. Click tiếp thì đang là desc (▼△) chuyển thành (▲▽) và gọi API List employees để sort tiếp
B31: 12 | D31: Danh sách ID nhân viên | M31: O | O31: － | Q31: Link | V31: － | AX31: Hiển thị danh sách ID nhân viên lấy từ API Click vào từng ID sẽ gọi API Get Employee và chuyển sang màn hình view chi tiết nhân viên ADM003
B32: 13 | D32: Danh sách tên nhân viên | M32: O | O32: － | Q32: Label | V32: － | AX32: Hiển thị danh sách tên nhân viên tương ứng với từng ID lấy từ API
B33: 14 | D33: Danh sách ngày sinh nhân viên | M33: O | O33: － | Q33: Label | V33: － | AX33: Hiển thi danh sách ngày sinh nhân viên tương ứng với từng ID lấy từ API
B34: 15 | D34: Danh sách phòng ban nhân viên | M34: O | O34: － | Q34: Label | V34: － | AX34: Hiển thi danh sách phòng ban nhân viên tương ứng với từng ID lấy từ API
B35: 16 | D35: Danh sách email nhân viên | M35: O | O35: － | Q35: Label | V35: － | AX35: Hiển thi danh sách email nhân viên tương ứng với từng ID lấy từ API
B36: 17 | D36: Danh sách số điện thoại nhân viên | M36: O | O36: － | Q36: Label | V36: － | AX36: Hiển thi danh sách Số điện thoại nhân viên tương ứng với từng ID lấy từ API
B37: 18 | D37: Danh sách chứng chỉ JP nhân viên | M37: O | O37: － | Q37: Label | V37: － | AX37: Hiển thi danh sách chứng chỉ JP nhân viên tương ứng với từng ID lấy từ API
B38: 19 | D38: Danh sách ngày hết han chứng chỉ JP nhân viên | M38: O | O38: － | Q38: Label | V38: － | AX38: Hiển thi danh sách ngày hết hạn chứng chỉ JP nhân viên tương ứng với từng ID lấy từ API
B39: 20 | D39: Danh sách điểm thi chứng chỉ JP nhân viên | M39: O | O39: － | Q39: Label | V39: － | AX39: Hiển thi danh sách điểm thi chứng chỉ JP nhân viên tương ứng với từng ID lấy từ API
B40: 21 | D40: Phân trang | M40: － | O40: － | Q40: Button | AX40: Button phân trang
B41: 22 | D41: Footer | M41: O | O41: － | Q41: Label | AX41: Text cố định
B43: ■ Nhân viên > Chi tiết nhân viên (ADM003)
B44: No | D44: Tên hạng mục | M44: I/O | O44: Bắt buộc | Q44: Loại control | V44: Type | Z44: Min ký tự | AB44: Max ký tự | AD44: Format | AH44: Mapping hạng mục | AX44: Note
AH45: API tham chiếu | AN45: Trường tham chiếu
B46: 1 | D46: Logo | M46: O | O46: － | Q46: Image | V46: － | AX46: Logo công ty + text tên cty: Luvina Software
...

Sheet API sử dụng
A1: Tên system | K1: Loại system | W1: =IF(Bìa!W1="","",Bìa!W1) -> TKCB | AP1: Người tạo | AT1: Ngày tạo | AY1: Người update | BC1: Ngày update | BH1: Version
A2: =IF(Bìa!A2="","",Bìa!A2) -> Manage User | K2: =IF(Bìa!K2="","",Bìa!K2) -> Thiết kế màn hình | AP2: =IF(Bìa!AP2="","",Bìa!AP2) -> LongLD | AT2: =IF(Bìa!AT2="","",Bìa!AT2) -> 45078 | AY2: =IF(Bìa!AY2="","",Bìa!AY2) -> LongLD | BC2: =IF(Bìa!BC2="","",Bìa!BC2) -> 45078 | BH2: =IF(Bìa!BH2="","",Bìa!BH2) -> 0.1
A4: Category chức năng | H4: =IF(Bìa!H4="","",Bìa!H4) | U4: Hạng mục | Z4: =IF(Bìa!Z4="","",Bìa!Z4) | AP4: API sử dụng
B7: ■Danh sách API sử dụng
D9: No. | F9: Tên service | P9: Tên vật lý | AF9: Phương thức | AL9: File tham chiếu
D10: 1 | F10: Login | P10: /login | AF10: POST | AL10: TKAPI_Login.xslx
D11: 2 | F11: List departments | P11: /department | AF11: GET | AL11: TKAPI_ListDepartments.xslx
D12: 3 | F12: List certifications | P12: /certification | AF12: GET | AL12: TKAPI_ListCertifications.xslx
D13: 4 | F13: List employees | P13: /employee | AF13: GET | AL13: TKAPI_ListEmployee.xslx
D14: 5 | F14: Add employee | P14: /employee | AF14: POST | AL14: TKAPI_AddEmployee.xslx
D15: 6 | F15: Edit employee | P15: /employee | AF15: PUT | AL15: TKAPI_UpdateEmployee.xslx
D16: 7 | F16: Delete employee | P16: /employee/:id | AF16: DELETE | AL16: TKAPI_DeleteEmployee.xslx
D17: 8 | F17: Get employee | P17: /employee/:id | AF17: GET | AL17: TKAPI_GetEmployee.xslx

Sheet Flow xử lý
A1: Tên system | K1: Loại system | W1: =IF(Bìa!W1="","",Bìa!W1) -> TKCB | AP1: Người tạo | AT1: Ngày tạo | AY1: Người update | BC1: Ngày update | BH1: Version
A2: =IF(Bìa!A2="","",Bìa!A2) -> Manage User | K2: =IF(Bìa!K2="","",Bìa!K2) -> Thiết kế màn hình | AP2: =IF(Bìa!AP2="","",Bìa!AP2) -> LongLD | AT2: =IF(Bìa!AT2="","",Bìa!AT2) -> 45078 | AY2: =IF(Bìa!AY2="","",Bìa!AY2) -> LongLD | BC2: =IF(Bìa!BC2="","",Bìa!BC2) -> 45078 | BH2: =IF(Bìa!BH2="","",Bìa!BH2) -> 0.1
A4: Category chức năng | H4: =IF(Bìa!H4="","",Bìa!H4) | U4: Hạng mục | Z4: =IF(Bìa!Z4="","",Bìa!Z4) | AP4: Flow xử lý
B7: ■Xử lý login
B37: ■Xử lý hiển thị search list nhân viên
B66: ■Xử lý hiển thị view chi tiết nhân viên
B97: ■Xử lý delete nhân viên
B120: ■Xử lý add/edit nhân viên
D122: Hiển thị ban đầu
D158: Button Confirm
C183: ■Xử lý confirm add/update nhân viên
D185: Hiển thị ban đầu
D211: Button Update

Sheet Chi tiết xử lý
A1: Tên system | K1: Loại system | W1: =IF(Bìa!W1="","",Bìa!W1) -> TKCB | AP1: Người tạo | AT1: Ngày tạo | AY1: Người update | BC1: Ngày update | BH1: Version
A2: =IF(Bìa!A2="","",Bìa!A2) -> Manage User | K2: =IF(Bìa!K2="","",Bìa!K2) -> Thiết kế màn hình | AP2: =IF(Bìa!AP2="","",Bìa!AP2) -> LongLD | AT2: =IF(Bìa!AT2="","",Bìa!AT2) -> 45078 | AY2: =IF(Bìa!AY2="","",Bìa!AY2) -> LongLD | BC2: =IF(Bìa!BC2="","",Bìa!BC2) -> 45078 | BH2: =IF(Bìa!BH2="","",Bìa!BH2) -> 0.1
A4: Category chức năng | H4: =IF(Bìa!H4="","",Bìa!H4) | U4: Hạng mục | Z4: =IF(Bìa!Z4="","",Bìa!Z4) | AP4: Chi tiết xử lý
B7: I. Xử lý common
C8: Phần header: (tất cả các màn hình, trừ màn hình login)
D9: Logout:
E10: Clear session storage, di chuyển về màn hình login
D12: Top
E13: Thực hiện scroll lên top
C15: Lỗi gọi API
D16: Khi gọi API mà server trả về HTTP status code
E17: 5xx: redirect sang màn hình System error
E18: 401, 403: redirect sang màn hình Login
E19: Các lỗi khác thông báo tại màn hình
C21: Lỗi truy cập URL không tồn tại
D22: Khi user cố tình truy cập vào URL ko tồn tại, redirect sang màn hình System error với message "Page not found" (ER022)
C24: Lỗi bất thường xảy ra
D25: Redirect sang màn hình System error với message "System Error" (ER023)
C27: Hạng mục nhập date
D28: Hạng mục nhập date gồm textbox và icon calendar
D29: Trong đó textbox ko cho phép nhập trực tiếp bằng keyboard (disable)
D30: Muốn nhập user phải click chọn calendar từ icon calendar để mở popup calendar như hình dưới,
D31: User chọn 1 date từ popup calendar thì fill text vào textbox (định dạng yyyy/MM/dd)
E47: Khi cần disable thì ko cho click từ icon calendar
C49: Validate
D50: Tất cả các hạng mục nhập yêu cầu validate thì thực hiện validate ngay khi user tương tác với control
D51: Với các hạng mục có lỗi thì trên UI hightlight hạng mục đó (tô màu border thành màu đỏ), khi không có lỗi thì để như ban đầu (giống mock)
D52: Khi hạng mục lỗi, message lỗi hiển thị ngay dưới hạng mục, tô màu đỏ, khi ko có lỗi thì clear message lỗi
D53: Với các lỗi chung ko liên quan đến hạng mục như server trả về lỗi, gọi API ko thành công,... hiển thị message lỗi ngay dưới header của page (tô màu đỏ)
D54: Các hạng mục bắt buộc nhập hiển thị kí hiệu (*) màu đỏ ngay sau tiêu đề hạng mục (nếu hạng mục có tiêu đề)
C56: Focus và tab index
D57: Với các màn hình nhập: khi mới vào lần đầu, focus con trỏ vào hạng mục nhập đầu tiên
D58: Các hạng mục để tab index theo thứ tự từ trái qua phải, từ trên xuống dưới
C60: Dropdown:
D61: Tất cả các dropdown nếu ko đề cập gì đều có phần tử rỗng ở đầu
C63: Phân trang
D64: Hiển thị
E65: Luôn hiển thị button trang đầu tiên và trang cuối cùng. Nếu tổng số trang = 1 thì không hiển thị phần phân trang
E66: Hiển thị button trang hiện tại, kèm button trang ngay trước và trang ngay sau của trang hiện tại
G67: Ví dụ nếu đang ở trang 5, tổng số trang là 15 thì hiển thị như sau < 1 … 4 5 6 … 15 >
...

Sheet Phụ lục
A1: Tên system | K1: Loại system | W1: =IF(Bìa!W1="","",Bìa!W1) -> TKCB | AP1: Người tạo | AT1: Ngày tạo | AY1: Người update | BC1: Ngày update | BH1: Version
A2: =IF(Bìa!A2="","",Bìa!A2) -> Manage User | K2: =IF(Bìa!K2="","",Bìa!K2) -> Thiết kế màn hình | AP2: =IF(Bìa!AP2="","",Bìa!AP2) -> LongLD | AT2: =IF(Bìa!AT2="","",Bìa!AT2) -> 45078 | AY2: =IF(Bìa!AY2="","",Bìa!AY2) -> LongLD | BC2: =IF(Bìa!BC2="","",Bìa!BC2) -> 45078 | BH2: =IF(Bìa!BH2="","",Bìa!BH2) -> 0.1
A4: Category chức năng | H4: =IF(Bìa!H4="","",Bìa!H4) | U4: Hạng mục | Z4: =IF(Bìa!Z4="","",Bìa!Z4) | AP4: Phụ lục

Sheet List tồn đọng
A1: Tên system | K1: Loại system | W1: =IF(Bìa!W1="","",Bìa!W1) -> TKCB | AP1: Người tạo | AT1: Ngày tạo | AY1: Người update | BC1: Ngày update | BH1: Version
A2: =IF(Bìa!A2="","",Bìa!A2) -> Manage User | K2: =IF(Bìa!K2="","",Bìa!K2) -> Thiết kế màn hình | AP2: =IF(Bìa!AP2="","",Bìa!AP2) -> LongLD | AT2: =IF(Bìa!AT2="","",Bìa!AT2) -> 45078 | AY2: =IF(Bìa!AY2="","",Bìa!AY2) -> LongLD | BC2: =IF(Bìa!BC2="","",Bìa!BC2) -> 45078 | BH2: =IF(Bìa!BH2="","",Bìa!BH2) -> 0.1
A4: Category chức năng | H4: =IF(Bìa!H4="","",Bìa!H4) | U4: Hạng mục | AP4: List tồn đọng
C7: Danh sách xử lý tồn đọng
D9: No. | F9: Nội dung tồn đọng

Sheet Tham chiếu
A1: Tên system | K1: Loại system | W1: =IF(Bìa!W1="","",Bìa!W1) -> TKCB | AP1: Người tạo | AT1: Ngày tạo | AY1: Người update | BC1: Ngày update | BH1: Version
A2: =IF(Bìa!A2="","",Bìa!A2) -> Manage User | K2: =IF(Bìa!K2="","",Bìa!K2) -> Thiết kế màn hình | AP2: =IF(Bìa!AP2="","",Bìa!AP2) -> LongLD | AT2: =IF(Bìa!AT2="","",Bìa!AT2) -> 45078 | AY2: =IF(Bìa!AY2="","",Bìa!AY2) -> LongLD | BC2: =IF(Bìa!BC2="","",Bìa!BC2) -> 45078 | BH2: =IF(Bìa!BH2="","",Bìa!BH2) -> 0.1
A4: Category chức năng | H4: =IF(Bìa!H4="","",Bìa!H4) | U4: Hạng mục | AP4: Tham chiếu
C7: Danh sách tài liệu tham chiếu
D9: No. | F9: Mã tham chiếu | L9: Tài liệu tham chiếu
D10: 1 | F10: TKMH | L10: Flow nghiệp vụ_di chuyển màn hình.xlsx
